<?xml version="1.0"?>
<sdf version="1.6">
  <model name="turtlebot3_burger_cam">
    <pose>0.0 0.0 0.0 0.0 0.0 0.0</pose>

    <link name="base_footprint" />

    <link name="base_link">

      <inertial>
        <pose>-0.033 0 0.070 0 0 0</pose>
        <inertia>
          <ixx>2.2124416e-03</ixx>
          <ixy>0.0</ixy>
          <ixz>0.0</ixz>
          <iyy>2.1193702e-03</iyy>
          <iyz>0.0</iyz>
          <izz>2.0064271e-03</izz>
        </inertia>
        <mass>8.2573504e-01</mass>
      </inertial>

      <collision name="base_collision">
        <pose>-0.032 0 0.070 0 0 0</pose>
        <geometry>
          <box>
            <size>0.140 0.140 0.140</size>
          </box>
        </geometry>
      </collision>

      <visual name="base_visual">
        <pose>-0.032 0 0 0 0 0</pose>
        <geometry>
          <mesh>
            <uri>model://catapaf_common/meshes/bases/burger_base.stl</uri>
            <scale>0.001 0.001 0.001</scale>
          </mesh>
        </geometry>
        <material>
          <ambient>0.3 0.3 0.3 1.0</ambient>
          <diffuse>0.3 0.3 0.3 1.0</diffuse>
        </material>
      </visual>
    </link>

    <link name="imu_link">
      <sensor name="tb3_imu" type="imu">
        <always_on>true</always_on>
        <update_rate>200</update_rate>
        <topic>imu</topic>
        <imu>
          <angular_velocity>
            <x>
              <noise type="gaussian">
                <mean>0.0</mean>
                <stddev>2e-4</stddev>
              </noise>
            </x>
            <y>
              <noise type="gaussian">
                <mean>0.0</mean>
                <stddev>2e-4</stddev>
              </noise>
            </y>
            <z>
              <noise type="gaussian">
                <mean>0.0</mean>
                <stddev>2e-4</stddev>
              </noise>
            </z>
          </angular_velocity>
          <linear_acceleration>
            <x>
              <noise type="gaussian">
                <mean>0.0</mean>
                <stddev>1.7e-2</stddev>
              </noise>
            </x>
            <y>
              <noise type="gaussian">
                <mean>0.0</mean>
                <stddev>1.7e-2</stddev>
              </noise>
            </y>
            <z>
              <noise type="gaussian">
                <mean>0.0</mean>
                <stddev>1.7e-2</stddev>
              </noise>
            </z>
          </linear_acceleration>
        </imu>
      </sensor>
    </link>

    <link name="base_scan">
      <inertial>
        <pose>-0.020 0 0.161 0 0 0</pose>
        <inertia>
          <ixx>47.43e-06</ixx>
          <ixy>0.000</ixy>
          <ixz>0.000</ixz>
          <iyy>79.51e-06</iyy>
          <iyz>0.000</iyz>
          <izz>102.75e-06</izz>
        </inertia>
        <mass>0.114</mass>
      </inertial>

      <collision name="lidar_sensor_collision">
        <pose>-0.020 0 0.161 0 0 0</pose>
        <geometry>
          <cylinder>
            <radius>0.0508</radius>
            <length>0.055</length>
          </cylinder>
        </geometry>
      </collision>

      <visual name="lidar_sensor_visual">
        <pose>-0.032 0 0.171 0 0 0</pose>
        <geometry>
          <mesh>
            <uri>model://catapaf_common/meshes/sensors/lds.stl</uri>
            <scale>0.001 0.001 0.001</scale>
          </mesh>
        </geometry>
        <material>
          <ambient>0.2 0.2 0.2 1.0</ambient>
          <diffuse>0.2 0.2 0.2 1.0</diffuse>
        </material>
      </visual>

      <sensor name="hls_lfcd_lds" type="gpu_lidar">
        <always_on>true</always_on>
        <visualize>true</visualize>
        <pose>-0.032 0 0.171 0 0 0</pose>
        <update_rate>5</update_rate>
        <topic>scan</topic>
        <gz_frame_id>base_scan</gz_frame_id>
        <lidar>
          <scan>
            <horizontal>
              <samples>360</samples>
              <resolution>1.000000</resolution>
              <min_angle>0.000000</min_angle>
              <max_angle>6.280000</max_angle>
            </horizontal>
          </scan>
          <range>
            <min>0.120000</min>
            <max>3.5</max>
            <resolution>0.015000</resolution>
          </range>
          <noise>
            <type>gaussian</type>
            <mean>0.0</mean>
            <stddev>0.01</stddev>
          </noise>
        </lidar>
      </sensor>
    </link>

    <link name="wheel_left_link">

      <inertial>
        <pose>0 0.08 0.023 -1.57 0 0</pose>
        <inertia>
          <ixx>1.1175580e-05</ixx>
          <ixy>0.0</ixy>
          <ixz>0.0</ixz>
          <iyy>1.1192413e-05</iyy>
          <iyz>0.0</iyz>
          <izz>2.0712558e-05</izz>
        </inertia>
        <mass>2.8498940e-02</mass>
      </inertial>

      <collision name="wheel_left_collision">
        <pose>0 0.08 0.023 -1.57 0 0</pose>
        <geometry>
          <cylinder>
            <radius>0.033</radius>
            <length>0.018</length>
          </cylinder>
        </geometry>
        <surface>
          <!-- This friction pamareter don't contain reliable data!! -->
          <friction>
            <ode>
              <mu>1.0</mu>
              <mu2>1.0</mu2>
            </ode>
          </friction>
          <contact>
            <ode>
              <soft_cfm>0</soft_cfm>
              <soft_erp>0.2</soft_erp>
              <kp>1e+5</kp>
              <kd>1</kd>
              <max_vel>0.01</max_vel>
              <min_depth>0.001</min_depth>
            </ode>
          </contact>
        </surface>
      </collision>

      <visual name="wheel_left_visual">
        <pose>0 0.08 0.023 0 0 0</pose>
        <geometry>
          <mesh>
            <uri>model://catapaf_common/meshes/wheels/left_tire.stl</uri>
            <scale>0.001 0.001 0.001</scale>
          </mesh>
        </geometry>
        <material>
          <ambient>0.2 0.2 0.2 1.0</ambient>
          <diffuse>0.2 0.2 0.2 1.0</diffuse>
        </material>
      </visual>
    </link>

    <link name="wheel_right_link">

      <inertial>
        <pose>0.0 -0.08 0.023 -1.57 0 0</pose>
        <inertia>
          <ixx>1.1175580e-05</ixx>
          <ixy>0.0</ixy>
          <ixz>0.0</ixz>
          <iyy>1.1192413e-05</iyy>
          <iyz>0.0</iyz>
          <izz>2.0712558e-05</izz>
        </inertia>
        <mass>2.8498940e-02</mass>
      </inertial>

      <collision name="wheel_right_collision">
        <pose>0.0 -0.08 0.023 -1.57 0 0</pose>
        <geometry>
          <cylinder>
            <radius>0.033</radius>
            <length>0.018</length>
          </cylinder>
        </geometry>
        <surface>
          <!-- This friction pamareter don't contain reliable data!! -->
          <friction>
            <ode>
              <mu>1.0</mu>
              <mu2>1.0</mu2>
            </ode>
          </friction>
          <contact>
            <ode>
              <soft_cfm>0</soft_cfm>
              <soft_erp>0.2</soft_erp>
              <kp>1e+5</kp>
              <kd>1</kd>
              <max_vel>0.01</max_vel>
              <min_depth>0.001</min_depth>
            </ode>
          </contact>
        </surface>
      </collision>

      <visual name="wheel_right_visual">
        <pose>0.0 -0.08 0.023 0 0 0</pose>
        <geometry>
          <mesh>
            <uri>model://catapaf_common/meshes/wheels/right_tire.stl</uri>
            <scale>0.001 0.001 0.001</scale>
          </mesh>
        </geometry>
        <material>
          <ambient>0.2 0.2 0.2 1.0</ambient>
          <diffuse>0.2 0.2 0.2 1.0</diffuse>
        </material>
      </visual>
    </link>

    <link name='caster_back_link'>
      <pose>-0.081 0 -0.004 -1.57 0 0</pose>
      <inertial>
        <mass>0.005</mass>
        <inertia>
          <ixx>1.0e-07</ixx>
          <ixy>0.000</ixy>
          <ixz>0.000</ixz>
          <iyy>1.0e-07</iyy>
          <iyz>0.000</iyz>
          <izz>1.0e-07</izz>
        </inertia>
      </inertial>
      <collision name='collision'>
        <geometry>
          <sphere>
            <radius>0.005000</radius>
          </sphere>
        </geometry>
        <surface>
          <contact>
            <ode>
              <soft_cfm>0</soft_cfm>
              <soft_erp>0.2</soft_erp>
              <kp>1e+5</kp>
              <kd>1</kd>
              <max_vel>0.01</max_vel>
              <min_depth>0.001</min_depth>
            </ode>
          </contact>
        </surface>
      </collision>
    </link>


    <!-- OAK-D Pro Camera -->
    <link name="oak_d_pro_camera">
      <pose>0.065 0 0.11 0 0 0</pose>
      <inertial>
        <pose>0 0 0 0 0 0</pose>
        <mass>0.091</mass>
        <inertia>
          <ixx>1e-4</ixx>
          <ixy>0.0</ixy>
          <ixz>0.0</ixz>
          <iyy>1e-4</iyy>
          <iyz>0.0</iyz>
          <izz>1e-4</izz>
        </inertia>
      </inertial>

      <collision name="oak_d_pro_collision">
        <pose>0 -0.005 -0.01 0 0 0</pose>
        <geometry>
          <box>
            <size>0.1 0.03 0.02</size>
          </box>
        </geometry>
      </collision>

      <visual name="oak_d_pro_visual">
        <pose>0 0 0 0 0 0</pose>
        <geometry>
          <mesh>
            <uri>model://catapaf_common/meshes/sensors/OAK-D-PRO.stl</uri>
            <scale>1 1 1</scale>
          </mesh>
        </geometry>
        <material>
          <ambient>0.3 0.3 0.3 1.0</ambient>
          <diffuse>0.3 0.3 0.3 1.0</diffuse>
        </material>
      </visual>

      <sensor name='oak_d_pro_color' type='camera'>
        <pose>0 0 0 0 0 0</pose>
        <update_rate>10</update_rate>
        <always_on>1</always_on>
        <visualize>true</visualize>
        <topic>camera/image_raw</topic>
        <gz_frame_id>oak_d_pro_color_optical_frame</gz_frame_id>
        <camera>
          <horizontal_fov>1.3962634</horizontal_fov>
          <image>
            <width>640</width>
            <height>480</height>
            <format>RGB_INT8</format>
          </image>
          <clip>
            <near>0.15</near>
            <far>300</far>
          </clip>
          <noise>
            <type>gaussian</type>
            <mean>0.0</mean>
            <stddev>0.007</stddev>
          </noise>
        </camera>
      </sensor>

      <sensor name='oak_d_pro_depth' type='depth_camera'>
        <update_rate>30</update_rate>
        <always_on>1</always_on>
        <visualize>true</visualize>
        <topic>depth_camera/image</topic>
        <gz_frame_id>oak_d_pro_depth_optical_frame</gz_frame_id>
        <camera>
          <horizontal_fov>1.047</horizontal_fov>
          <image>
            <width>640</width>
            <height>480</height>
            <format>R_FLOAT32</format>
          </image>
          <clip>
            <near>0.1</near>
            <far>100.0</far>
          </clip>
          <depth_camera>
            <output>depths</output>
            <clip>
              <near>0.1</near>
              <far>10.0</far>
            </clip>
          </depth_camera>
        </camera>
      </sensor>
    </link>

    <link name="oak_d_pro_color_optical_frame" />

    <joint name="joint_oak_d_pro_color_optical_frame" type="fixed">
      <parent>oak_d_pro_camera</parent>
      <child>oak_d_pro_color_optical_frame</child>
      <pose>0 0 0 -1.5708 0 -1.5708</pose>
    </joint>

    <link name="oak_d_pro_depth_optical_frame" />

    <joint name="joint_oak_d_pro_depth_optical_frame" type="fixed">
      <parent>oak_d_pro_camera</parent>
      <child>oak_d_pro_depth_optical_frame</child>
      <pose>0 0 0 -1.5708 0 -1.5708</pose>
    </joint>

    <!-- Catapaf Base -->
    <link name="catapaf_base">
      <pose>-0.03 -0.09 0.11 0 0 0</pose>
      <inertial>
        <pose>0 0 0 0 0 0</pose>
        <mass>0.15</mass>
        <inertia>
          <ixx>0.0002</ixx>
          <ixy>0.0</ixy>
          <ixz>0.0</ixz>
          <iyy>0.0002</iyy>
          <iyz>0.0</iyz>
          <izz>0.0002</izz>
        </inertia>
      </inertial>

      <collision name="catapaf_base_collision">
        <pose>-0.02 0.02 0 0 0 0</pose>
        <geometry>
          <box>
            <size>0.08 0.05 0.03</size>
          </box>
        </geometry>
      </collision>

      <visual name="catapaf_base_visual">
        <pose>0 0 0 0 0 0</pose>
        <geometry>
          <mesh>
            <uri>model://catapaf_common/meshes/catapaf/baseEtServo.stl</uri>
            <scale>1 1 1</scale>
          </mesh>
        </geometry>
        <material>
          <ambient>1.0 0.5 0.0 1.0</ambient>
          <diffuse>1.0 0.5 0.0 1.0</diffuse>
        </material>
      </visual>
    </link>

    <!-- Catapaf Arm -->
    <link name="catapaf_arm">
      <pose>-0.03 -0.098 0.11 3.14159265359 3.14159265359 0</pose>
      <inertial>
        <pose>0.05596964 -0.00000099 -0.00621362 0 0 0</pose>
        <mass>0.05</mass>
        <inertia>
          <ixx>0.00000512</ixx>
          <ixy>-0.00000000</ixy>
          <ixz>0.00000175</ixz>
          <iyy>0.00003787</iyy>
          <iyz>0.00000000</iyz>
          <izz>0.00003918</izz>
        </inertia>
      </inertial>
      <collision name="catapaf_arm_collision">
        <origin xyz="0.0 0 0" />
        <geometry>
          <!-- <mesh
            filename="package://catapaf_gazebo/models/catapaf_common/meshes/catapaf/collider_godet.stl" /> -->
          <mesh>
            <uri>model://catapaf_common/meshes/catapaf/collider_godet.stl</uri>
            <scale>1 1 1</scale>
          </mesh>
        </geometry>
      </collision>

      <visual name="catapaf_arm_visual">
        <pose>0 0 0 0 0 0</pose>
        <geometry>
          <mesh>
            <uri>model://catapaf_common/meshes/catapaf/godetrvcm.stl</uri>
            <scale>1 1 1</scale>
          </mesh>
        </geometry>
        <material>
          <ambient>0.8 0.0 0.0 1.0</ambient>
          <diffuse>0.8 0.0 0.0 1.0</diffuse>
        </material>
      </visual>
    </link>


    <joint name="base_joint" type="fixed">
      <parent>base_footprint</parent>
      <child>base_link</child>
      <pose>0.0 0.0 0.010 0 0 0</pose>
    </joint>

    <joint name="wheel_left_joint" type="revolute">
      <parent>base_link</parent>
      <child>wheel_left_link</child>
      <pose>0.0 0.08 0.023 -1.57 0 0</pose>
      <axis>
        <xyz>0 0 1</xyz>
        <limit>
          <effort>20</effort>
        </limit>
      </axis>
    </joint>

    <joint name="wheel_right_joint" type="revolute">
      <parent>base_link</parent>
      <child>wheel_right_link</child>
      <pose>0.0 -0.08 0.023 -1.57 0 0</pose>
      <axis>
        <xyz>0 0 1</xyz>
        <limit>
          <effort>20</effort>
        </limit>
      </axis>
    </joint>

    <joint name='caster_back_joint' type='ball'>
      <parent>base_link</parent>
      <child>caster_back_link</child>
    </joint>

    <joint name="imu_joint" type="fixed">
      <parent>base_link</parent>
      <child>imu_link</child>
      <pose>-0.032 0 0.068 0 0 0</pose>
      <axis>
        <xyz>0 0 1</xyz>
      </axis>
    </joint>

    <joint name="lidar_joint" type="fixed">
      <parent>base_link</parent>
      <child>base_scan</child>
      <pose>-0.032 0 0.171 0 0 0</pose>
      <axis>
        <xyz>0 0 1</xyz>
      </axis>
    </joint>

    <joint name="joint_oak_d_pro_camera" type="fixed">
      <parent>base_link</parent>
      <child>oak_d_pro_camera</child>
      <pose>0.065 0 0.11 0 0 0</pose>
      <axis>
        <xyz>0 0 1</xyz>
      </axis>
    </joint>

    <joint name="catapaf_base_mount" type="fixed">
      <parent>base_link</parent>
      <child>catapaf_base</child>
      <pose relative_to="base_link">-0.03 -0.09 0.11 0 0 0</pose>
      <axis>
        <xyz>0 0 1</xyz>
      </axis>
    </joint>

    <joint name="catapaf_joint" type="revolute">
      <parent>catapaf_base</parent>
      <child>catapaf_arm</child>
      <pose>0 -0.008 0 3.14159265359 3.14159265359 0</pose>
      <axis>
        <xyz>0 1 0</xyz>
        <limit>
          <lower>-1.5</lower>
          <upper>1.3</upper>
          <effort>1.0</effort>
          <velocity>5.0</velocity>
        </limit>
        <dynamics>
          <damping>0.1</damping>
          <friction>0.1</friction>
        </dynamics>
      </axis>
    </joint>

    <plugin filename="gz-sim-diff-drive-system" name="gz::sim::systems::DiffDrive">
      <!-- wheels -->
      <left_joint>wheel_left_joint</left_joint>
      <right_joint>wheel_right_joint</right_joint>

      <!-- kinematics -->
      <wheel_separation>0.160</wheel_separation>
      <wheel_radius>0.033</wheel_radius>

      <!-- limits -->
      <max_linear_acceleration>1.0</max_linear_acceleration>

      <topic>cmd_vel</topic>
      <odom_topic>odom</odom_topic>
      <frame_id>odom</frame_id>
      <tf_topic>/tf</tf_topic>
      <odom_publisher_frequency>30</odom_publisher_frequency>
      <child_frame_id>base_footprint</child_frame_id>
    </plugin>

    <plugin filename="gz-sim-joint-state-publisher-system"
      name="gz::sim::systems::JointStatePublisher">
      <topic>joint_states</topic>
      <!-- <update_rate>30</update_rate> -->
      <joint_name>wheel_left_joint</joint_name>
      <joint_name>wheel_right_joint</joint_name>
      <joint_name>catapaf_joint</joint_name>
    </plugin>

    <!-- Joint Position Controller for Catapaf Arm -->
    <plugin filename="gz-sim-joint-position-controller-system"
      name="gz::sim::systems::JointPositionController">
      <joint_name>catapaf_joint</joint_name>
      <topic>catapaf_arm/position</topic>
      <p_gain>15.0</p_gain>
      <i_gain>0.1</i_gain>
      <d_gain>8.0</d_gain>
      <i_max>1.0</i_max>
      <i_min>-1.0</i_min>
      <cmd_max>50.0</cmd_max>
      <cmd_min>-50.0</cmd_min>
    </plugin>

    <plugin name="camera_info" filename="gz-sim-ros2-camera-system">
      <topic>camera/camera_info</topic>
    </plugin>

  </model>
</sdf>