<?xml version="1.0"?>
<!-- =================================================================================== -->
<!-- |    This document was autogenerated by xacro from catapaf.urdf.xacro             | -->
<!-- |    EDITING THIS FILE BY HAND IS NOT RECOMMENDED                                 | -->
<!-- =================================================================================== -->
<robot name="turtlebot3_burger">
  <!-- ====================================================== -->
  <!-- Materials -->
  <!-- ====================================================== -->
  <material name="black">
    <color rgba="0 0 0 1" />
  </material>
  <material name="dark">
    <color rgba="0.3 0.3 0.3 1" />
  </material>
  <material name="light_black">
    <color rgba="0.4 0.4 0.4 1" />
  </material>
  <material name="blue">
    <color rgba="0 0 0.8 1" />
  </material>
  <material name="green">
    <color rgba="0 0.8 0 1" />
  </material>
  <material name="grey">
    <color rgba="0.5 0.5 0.5 1" />
  </material>
  <material name="orange">
    <color rgba="1 0.4235 0.0392 1" />
  </material>
  <material name="brown">
    <color rgba="0.8706 0.8118 0.7647 1" />
  </material>
  <material name="red">
    <color rgba="0.8 0 0 1" />
  </material>
  <material name="white">
    <color rgba="1 1 1 1" />
  </material>
  <!-- ====================================================== -->
  <!-- Base footprint → base_link -->
  <!-- ====================================================== -->
  <link name="base_footprint" />
  <joint name="base_joint" type="fixed">
    <parent link="base_footprint" />
    <child link="base_link" />
    <origin rpy="0 0 0" xyz="0 0 0.010" />
  </joint>
  <link name="base_link">
    <visual>
      <origin rpy="0 0 0" xyz="-0.032 0 0" />
      <geometry>
        <mesh
          filename="/home/lefev/catapaf_ws/TurtleShot/src/robot_gazebo_sim/meshes/bases/burger_base.stl"
          scale="0.001 0.001 0.001" />
      </geometry>
      <material name="light_black" />
    </visual>
    <collision>
      <origin xyz="-0.032 0 0.070" />
      <geometry>
        <box size="0.140 0.140 0.143" />
      </geometry>
    </collision>
    <inertial>
      <origin xyz="-0.033 0 0.07" />
      <mass value="0.82573504" />
      <inertia ixx="0.0022124416" ixy="0" ixz="0" iyy="0.0021193702" iyz="0" izz="0.0020064271" />
    </inertial>
  </link>
  <!-- ====================================================== -->
  <!-- Wheels -->
  <!-- ====================================================== -->
  <joint name="wheel_left_joint" type="continuous">
    <parent link="base_link" />
    <child link="wheel_left_link" />
    <origin rpy="-1.57 0 0" xyz="0 0.08 0.023" />
    <axis xyz="0 0 1" />
  </joint>
  <link name="wheel_left_link">
    <visual>
      <origin rpy="1.57 0 0" />
      <geometry>
        <mesh
          filename="/home/lefev/catapaf_ws/TurtleShot/src/robot_gazebo_sim/meshes/wheels/left_tire.stl"
          scale="0.001 0.001 0.001" />
      </geometry>
      <material name="dark" />
    </visual>
    <collision>
      <geometry>
        <cylinder length="0.018" radius="0.033" />
      </geometry>
    </collision>
    <inertial>
      <mass value="0.02849894" />
      <inertia ixx="1.117558e-05" ixy="0" ixz="0" iyy="1.1192413e-05" iyz="0" izz="2.0712558e-05" />
    </inertial>
  </link>
  <joint name="wheel_right_joint" type="continuous">
    <parent link="base_link" />
    <child link="wheel_right_link" />
    <origin rpy="-1.57 0 0" xyz="0 -0.08 0.023" />
    <axis xyz="0 0 1" />
  </joint>
  <link name="wheel_right_link">
    <visual>
      <origin rpy="1.57 0 0" />
      <geometry>
        <mesh
          filename="/home/lefev/catapaf_ws/TurtleShot/src/robot_gazebo_sim/meshes/wheels/right_tire.stl"
          scale="0.001 0.001 0.001" />
      </geometry>
    </visual>
    <collision>
      <geometry>
        <cylinder length="0.018" radius="0.033" />
      </geometry>
    </collision>
    <inertial>
      <origin xyz="0 0 0" />
      <mass value="0.02849894" />
      <inertia ixx="1.1175580e-05" ixy="0.0" ixz="0.0" iyy="1.1192413e-05" iyz="0.0"
        izz="2.0712558e-05" />
    </inertial>
  </link>
  <!-- ====================================================== -->
  <!-- Back caster -->
  <!-- ====================================================== -->
  <joint name="caster_back_joint" type="fixed">
    <parent link="base_link" />
    <child link="caster_back_link" />
    <origin rpy="-1.57 0 0" xyz="-0.081 0 -0.004" />
  </joint>
  <link name="caster_back_link">
    <collision>
      <origin xyz="0 0.001 0" />
      <geometry>
        <box size="0.030 0.009 0.020" />
      </geometry>
    </collision>
    <inertial>
      <origin xyz="0 0 0" />
      <mass value="0.005" />
      <inertia ixx="1e-07" ixy="0.0" ixz="0.0" iyy="1e-07" iyz="0.0" izz="1e-07" />
    </inertial>
  </link>
  <!-- ====================================================== -->
  <!-- IMU -->
  <!-- ====================================================== -->
  <joint name="imu_joint" type="fixed">
    <parent link="base_link" />
    <child link="imu_link" />
    <origin xyz="-0.032 0 0.068" />
  </joint>
  <link name="imu_link" />
  <!-- ====================================================== -->
  <!-- Lidar -->
  <!-- ====================================================== -->
  <joint name="scan_joint" type="fixed">
    <parent link="base_link" />
    <child link="base_scan" />
    <origin xyz="-0.032 0 0.172" />
  </joint>
  <link name="base_scan">
    <visual>
      <geometry>
        <mesh
          filename="/home/lefev/catapaf_ws/TurtleShot/src/robot_gazebo_sim/meshes/sensors/lds.stl"
          scale="0.001 0.001 0.001" />
      </geometry>
    </visual>
    <collision>
      <origin xyz="0.015 0 -0.0065" />
      <geometry>
        <cylinder length="0.0315" radius="0.055" />
      </geometry>
    </collision>
  </link>
  <!-- ====================================================== -->
  <!-- OAK-D Pro Camera -->
  <!-- ====================================================== -->
  <link name="oak_d_pro_camera">
    <visual>
      <origin xyz="0 0 0" rpy="0 0 1.57079632679" />
      <geometry>

        <mesh
          filename="/home/lefev/catapaf_ws/TurtleShot/src/robot_gazebo_sim/meshes/sensors/OAK-D-PRO.stl" />
      </geometry>
    </visual>
    <collision>
      <origin xyz="0 -0.005 -0.01" />
      <geometry>
        <box size="0.1 0.03 0.02" />
      </geometry>
    </collision>
    <inertial>
      <origin xyz="0 0 0" />
      <mass value="0.091" />
      <inertia ixx="1e-4" ixy="0.0" ixz="0.0" iyy="1e-4" iyz="0.0" izz="1e-4" />
    </inertial>
  </link>
  <joint name="joint_oak_d_pro_camera" type="fixed">
    <parent link="base_link" />
    <child link="oak_d_pro_camera" />
    <origin xyz="0.065 0 0.11" rpy="0 0 0" />
  </joint>
  <link name="oak_d_pro_color_optical_frame" />
  <joint name="joint_oak_d_pro_color_optical_frame" type="fixed">
    <parent link="oak_d_pro_camera" />
    <child link="oak_d_pro_color_optical_frame" />
    <origin xyz="0 0 0" rpy="-1.57079632679 0 -1.57079632679" />
  </joint>
  <link name="oak_d_pro_depth_optical_frame" />

  <joint name="joint_oak_d_pro_depth_optical_frame" type="fixed">
    <parent link="oak_d_pro_camera" />
    <child link="oak_d_pro_depth_optical_frame" />
    <origin xyz="0 0 0" rpy="-1.57079632679 0 -1.57079632679" />
  </joint>

  <!-- ====================================================== -->
  <!-- CATAPAF BASE -->
  <!-- ====================================================== -->
  <link name="catapaf_base">
    <visual>
      <geometry>
        <mesh
          filename="/home/lefev/catapaf_ws/TurtleShot/src/robot_gazebo_sim/meshes/catapaf/baseEtServo.stl" />
      </geometry>
    </visual>
    <collision>
      <origin xyz="-0.02 0.02 0" />
      <geometry>
        <box size="0.08 0.05 0.03" />
      </geometry>
    </collision>
    <inertial>
      <origin xyz="0 0 0" />
      <mass value="0.15" />
      <inertia ixx="0.0002" ixy="0" ixz="0" iyy="0.0002" iyz="0" izz="0.0002" />
    </inertial>
  </link>
  <joint name="catapaf_base_mount" type="fixed">
    <parent link="base_link" />
    <child link="catapaf_base" />
    <origin xyz="-0.03 -0.09 0.11" />
  </joint>
  <!-- ====================================================== -->
  <!-- CATAPAF ARM -->
  <!-- ====================================================== -->
  <link name="catapaf_arm">
    <visual>
      <geometry>
        <mesh
          filename="/home/lefev/catapaf_ws/TurtleShot/src/robot_gazebo_sim/meshes/catapaf/catapaf.stl" />
      </geometry>
    </visual>
    <collision>
      <origin xyz="0.04 0 0" />
      <geometry>
        <box size="0.12 0.05 0.03" />
      </geometry>
    </collision>
    <inertial>
      <origin xyz="0.05596964 -0.00000099 -0.00621362" />
      <mass value="0.05000000" />
      <inertia ixx="0.00000512" ixy="-0.00000000" ixz="0.00000175" iyy="0.00003787" iyz="0.00000000"
        izz="0.00003918" />
    </inertial>
  </link>
  <joint name="catapaf_joint" type="revolute">
    <parent link="catapaf_base" />
    <child link="catapaf_arm" />
    <origin xyz="0 -0.008 0" />
    <axis xyz="0 1 0" />
    <limit effort="1.0" lower="-1.5" upper="1.3" velocity="5.0" />
  </joint>

  <gazebo>
    <plugin name="differential_drive_controller" filename="libgazebo_ros_diff_drive.so">
      <update_rate>15</update_rate>

      <!-- Wheels -->
      <left_joint>wheel_left_joint</left_joint>
      <right_joint>wheel_right_joint</right_joint>

      <!-- Kinematics -->
      <wheel_separation>0.160</wheel_separation>
      <wheel_diameter>0.066</wheel_diameter>

      <!-- Limits -->
      <max_wheel_torque>20</max_wheel_torque>
      <max_wheel_acceleration>1.0</max_wheel_acceleration>

      <!-- Input/Output -->
      <command_topic>cmd_vel</command_topic>
      <odometry_topic>odom</odometry_topic>
      <odometry_frame>odom</odometry_frame>
      <robot_base_frame>base_footprint</robot_base_frame>

      <!-- Publish -->
      <publish_odom>true</publish_odom>
      <publish_odom_tf>true</publish_odom_tf>
      <publish_wheel_tf>true</publish_wheel_tf>
    </plugin>
  </gazebo>

  <!-- LiDAR Sensor Plugin -->
  <gazebo reference="base_scan">
    <sensor type="ray" name="lds_lfcd_sensor">
      <pose>0 0 0 0 0 0</pose>
      <visualize>false</visualize>
      <update_rate>10</update_rate>
      <ray>
        <scan>
          <horizontal>
            <samples>360</samples>
            <resolution>1</resolution>
            <min_angle>0.0</min_angle>
            <max_angle>6.28319</max_angle>
          </horizontal>
        </scan>
        <range>
          <min>0.12</min>
          <max>3.5</max>
          <resolution>0.015</resolution>
        </range>
        <noise>
          <type>gaussian</type>
          <mean>0.0</mean>
          <stddev>0.01</stddev>
        </noise>
      </ray>
      <plugin name="gazebo_ros_lds_lfcd_controller" filename="libgazebo_ros_ray_sensor.so">
        <ros>
          <remapping>~/out:=scan</remapping>
        </ros>
        <output_type>sensor_msgs/LaserScan</output_type>
        <frame_name>base_scan</frame_name>
      </plugin>
    </sensor>
  </gazebo>

  <!-- IMU Sensor Plugin -->
  <gazebo reference="imu_link">
    <sensor type="imu" name="imu">
      <always_on>true</always_on>
      <update_rate>50</update_rate>
      <visualize>false</visualize>
      <plugin filename="libgazebo_ros_imu_sensor.so" name="imu_plugin">
        <ros>
          <remapping>~/out:=imu</remapping>
        </ros>
        <initial_orientation_as_reference>false</initial_orientation_as_reference>
        <frame_name>imu_link</frame_name>
      </plugin>
    </sensor>
  </gazebo>

  <!-- Gazebo material properties -->
  <gazebo reference="base_link">
    <material>Gazebo/DarkGrey</material>
  </gazebo>

  <gazebo reference="wheel_left_link">
    <mu1>0.1</mu1>
    <mu2>0.1</mu2>
    <kp>500000.0</kp>
    <kd>10.0</kd>
    <minDepth>0.001</minDepth>
    <maxVel>0.1</maxVel>
    <material>Gazebo/FlatBlack</material>
  </gazebo>

  <gazebo reference="wheel_right_link">
    <mu1>0.1</mu1>
    <mu2>0.1</mu2>
    <kp>500000.0</kp>
    <kd>10.0</kd>
    <minDepth>0.001</minDepth>
    <maxVel>0.1</maxVel>
    <material>Gazebo/FlatBlack</material>
  </gazebo>

  <gazebo reference="caster_back_link">
    <mu1>0.1</mu1>
    <mu2>0.1</mu2>
    <kp>1000000.0</kp>
    <kd>100.0</kd>
    <minDepth>0.001</minDepth>
    <maxVel>1.0</maxVel>
    <material>Gazebo/FlatBlack</material>
  </gazebo>

  <!-- OAK-D Pro Camera Sensor Plugin -->
  <gazebo reference="oak_d_pro_camera">
    <sensor type="camera" name="camera_sensor">
      <update_rate>10.0</update_rate>
      <visualize>true</visualize>
      <camera name="camera">
        <horizontal_fov>1.3962634</horizontal_fov>
        <image>
          <width>640</width>
          <height>480</height>
          <format>R8G8B8</format>
        </image>
        <clip>
          <near>0.15</near>
          <far>300</far>
        </clip>
        <noise>
          <type>gaussian</type>
          <mean>0.0</mean>
          <stddev>0.007</stddev>
        </noise>
      </camera>
      <plugin name="camera_controller" filename="libgazebo_ros_camera.so">
        <ros>
          <remapping>~/image_raw:=camera/image_raw</remapping>
          <remapping>~/camera_info:=camera/camera_info</remapping>
        </ros>
        <frame_name>oak_d_pro_color_optical_frame</frame_name>
      </plugin>
    </sensor>
    <material>Gazebo/DarkGrey</material>
  </gazebo>
</robot>
<!-- appel direct si utilisé comme fichier URDF principal -->