<?xml version="1.0"?>
<robot name="turtlebot3_burger" xmlns:xacro="http://www.ros.org/wiki/xacro">
    <xacro:macro name="turtlebot_catapaf" params="prefix">

        <!-- ====================================================== -->
        <!-- Materials -->
        <!-- ====================================================== -->
        <material name="black">
            <color rgba="0 0 0 1" />
        </material>
        <material name="dark">
            <color rgba="0.3 0.3 0.3 1" />
        </material>
        <material name="light_black">
            <color rgba="0.4 0.4 0.4 1" />
        </material>
        <material name="blue">
            <color rgba="0 0 0.8 1" />
        </material>
        <material name="green">
            <color rgba="0 0.8 0 1" />
        </material>
        <material name="grey">
            <color rgba="0.5 0.5 0.5 1" />
        </material>
        <material name="orange">
            <color rgba="1 0.4235 0.0392 1" />
        </material>
        <material name="brown">
            <color rgba="0.8706 0.8118 0.7647 1" />
        </material>
        <material name="red">
            <color rgba="0.8 0 0 1" />
        </material>
        <material name="white">
            <color rgba="1 1 1 1" />
        </material>

        <!-- ====================================================== -->
        <!-- Base footprint → base_link -->
        <!-- ====================================================== -->
        <link name="base_footprint" />

        <joint name="base_joint" type="fixed">
            <parent link="base_footprint" />
            <child link="base_link" />
            <origin xyz="0 0 0.010" rpy="0 0 0" />
        </joint>

        <link name="base_link">
            <visual>
                <origin xyz="-0.032 0 0" rpy="0 0 0" />
                <geometry>
                    <mesh filename="package://catapaf_description/meshes/bases/burger_base.stl"
                        scale="0.001 0.001 0.001" />
                </geometry>
                <material name="light_black" />
            </visual>

            <collision>
                <origin xyz="-0.032 0 0.070" />
                <geometry>
                    <box size="0.140 0.140 0.143" />
                </geometry>
            </collision>

            <inertial>
                <origin xyz="-0.033 0 0.07" />
                <mass value="0.82573504" />
                <inertia ixx="0.0022124416" ixy="0" ixz="0"
                    iyy="0.0021193702" iyz="0" izz="0.0020064271" />
            </inertial>
        </link>

        <!-- ====================================================== -->
        <!-- Wheels -->
        <!-- ====================================================== -->

        <joint name="wheel_left_joint" type="continuous">
            <parent link="base_link" />
            <child link="wheel_left_link" />
            <origin xyz="0 0.08 0.023" rpy="-1.57 0 0" />
            <axis xyz="0 0 1" />
        </joint>

        <link name="wheel_left_link">
            <visual>
                <origin rpy="1.57 0 0" />
                <geometry>
                    <mesh filename="package://catapaf_description/meshes/wheels/left_tire.stl"
                        scale="0.001 0.001 0.001" />
                </geometry>
                <material name="dark" />
            </visual>

            <collision>
                <geometry>
                    <cylinder length="0.018" radius="0.033" />
                </geometry>
            </collision>

            <inertial>
                <mass value="0.02849894" />
                <inertia ixx="1.117558e-05" iyy="1.1192413e-05" izz="2.0712558e-05"
                    ixy="0" ixz="0" iyz="0" />
            </inertial>
        </link>

        <joint name="wheel_right_joint" type="continuous">
            <parent link="base_link" />
            <child link="wheel_right_link" />
            <origin xyz="0 -0.08 0.023" rpy="-1.57 0 0" />
            <axis xyz="0 0 1" />
        </joint>

        <link name="wheel_right_link">
            <visual>
                <origin rpy="1.57 0 0" />
                <geometry>
                    <mesh filename="package://catapaf_description/meshes/wheels/right_tire.stl"
                        scale="0.001 0.001 0.001" />
                </geometry>
            </visual>

            <collision>
                <geometry>
                    <cylinder length="0.018" radius="0.033" />
                </geometry>
            </collision>

            <inertial>
                <origin xyz="0 0 0" />
                <mass value="0.02849894" />
                <inertia
                    ixx="1.1175580e-05" ixy="0.0" ixz="0.0"
                    iyy="1.1192413e-05" iyz="0.0"
                    izz="2.0712558e-05" />
            </inertial>

        </link>

        <!-- ====================================================== -->
        <!-- Back caster -->
        <!-- ====================================================== -->
        <joint name="caster_back_joint" type="fixed">
            <parent link="base_link" />
            <child link="caster_back_link" />
            <origin xyz="-0.081 0 -0.004" rpy="-1.57 0 0" />
        </joint>

        <link name="caster_back_link">
            <collision>
                <origin xyz="0 0.001 0" />
                <geometry>
                    <box size="0.030 0.009 0.020" />
                </geometry>
            </collision>
            <inertial>
                <origin xyz="0 0 0" />
                <mass value="0.005" />
                <inertia
                    ixx="1e-07" ixy="0.0" ixz="0.0"
                    iyy="1e-07" iyz="0.0"
                    izz="1e-07" />
            </inertial>

        </link>

        <!-- ====================================================== -->
        <!-- IMU -->
        <!-- ====================================================== -->
        <joint name="imu_joint" type="fixed">
            <parent link="base_link" />
            <child link="imu_link" />
            <origin xyz="-0.032 0 0.068" />
        </joint>
        <link name="imu_link" />

        <!-- ====================================================== -->
        <!-- Lidar -->
        <!-- ====================================================== -->
        <joint name="scan_joint" type="fixed">
            <parent link="base_link" />
            <child link="base_scan" />
            <origin xyz="-0.032 0 0.172" />
        </joint>

        <link name="base_scan">
            <visual>
                <geometry>
                    <mesh filename="package://catapaf_description/meshes/sensors/lds.stl"
                        scale="0.001 0.001 0.001" />
                </geometry>
            </visual>
            <collision>
                <origin xyz="0.015 0 -0.0065" />
                <geometry>
                    <cylinder radius="0.055" length="0.0315" />
                </geometry>
            </collision>
        </link>

        <!-- ====================================================== -->
        <!-- OAK-D Pro Camera -->
        <!-- ====================================================== -->
        <link name="oak_d_pro_camera">
            <visual>
                <geometry>
                    <mesh filename="package://catapaf_description/meshes/sensors/OAK-D-PRO.stl" />
                </geometry>
            </visual>

            <collision>
                <origin xyz="0 -0.005 -0.01" />
                <geometry>
                    <box size="0.1 0.03 0.02" />
                </geometry>
            </collision>

            <inertial>
                <origin xyz="0 0 0" />
                <mass value="0.091" />
                <inertia
                    ixx="1e-4" ixy="0.0" ixz="0.0"
                    iyy="1e-4" iyz="0.0"
                    izz="1e-4" />
            </inertial>
        </link>

        <joint name="joint_oak_d_pro_camera" type="fixed">
            <parent link="base_link" />
            <child link="oak_d_pro_camera" />
            <origin xyz="0.065 0 0.11" rpy="1.57 0 1.57" />
        </joint>

        <link name="oak_d_pro_color_optical_frame" />
        <joint name="joint_oak_d_pro_color_optical_frame" type="fixed">
            <parent link="oak_d_pro_camera" />
            <child link="oak_d_pro_color_optical_frame" />
            <origin rpy="-1.5708 0 -1.5708" />
        </joint>

        <link name="oak_d_pro_depth_optical_frame" />
        <joint name="oak_d_pro_depth_optical_frame" type="fixed">
            <parent link="oak_d_pro_camera" />
            <child link="oak_d_pro_depth_optical_frame" />
            <origin rpy="-1.5708 0 -1.5708" />
        </joint>

        <!-- ====================================================== -->
        <!-- CATAPAF BASE -->
        <!-- ====================================================== -->
        <link name="catapaf_base">
            <visual>
                <geometry>
                    <mesh filename="package://catapaf_description/meshes/catapaf/baseEtServo.stl" />
                </geometry>
            </visual>
            <collision>
                <geometry>
                    <box size="0.10 0.08 0.06" />
                </geometry>
            </collision>
            <inertial>
                <origin xyz="0 0 0" />
                <mass value="0.15" />
                <inertia
                    ixx="0.0002" ixy="0" ixz="0"
                    iyy="0.0002" iyz="0"
                    izz="0.0002" />
            </inertial>

        </link>

        <joint name="catapaf_base_mount" type="fixed">
            <parent link="base_link" />
            <child link="catapaf_base" />
            <origin xyz="0.06 0 0.13" />
        </joint>

        <!-- ====================================================== -->
        <!-- CATAPAF ARM -->
        <!-- ====================================================== -->
        <link name="catapaf_arm">
            <visual>
                <geometry>
                    <mesh filename="package://catapaf_description/meshes/catapaf/catapaf.stl" />
                </geometry>
            </visual>

            <collision>
                <geometry>
                    <box size="0.12 0.015 0.015" />
                </geometry>
            </collision>

            <inertial>
                <origin xyz="0 0 0" />
                <mass value="0.05" />
                <inertia
                    ixx="0.00005" ixy="0" ixz="0"
                    iyy="0.00005" iyz="0"
                    izz="0.00005" />
            </inertial>

        </link>

        <joint name="catapaf_joint" type="revolute">
            <parent link="catapaf_base" />
            <child link="catapaf_arm" />
            <origin xyz="0 0 0.03" />
            <axis xyz="0 1 0" />
            <limit lower="-1.5" upper="1.3" velocity="5.0" effort="1.0" />
        </joint>

    </xacro:macro>
    <xacro:turtlebot_catapaf prefix="" />
</robot>

<!-- appel direct si utilisé comme fichier URDF principal -->