<?xml version="1.0"?>
<robot name="turtlebot3_burger_cam1"
  xmlns:xacro="http://ros.org/wiki/xacro">

  <!-- Materials -->
  <material name="black">
    <color rgba="0.0 0.0 0.0 1.0" />
  </material>

  <material name="dark">
    <color rgba="0.3 0.3 0.3 1.0" />
  </material>

  <material name="light_black">
    <color rgba="0.4 0.4 0.4 1.0" />
  </material>

  <material name="blue">
    <color rgba="0.0 0.0 0.8 1.0" />
  </material>

  <material name="green">
    <color rgba="0.0 0.8 0.0 1.0" />
  </material>

  <material name="grey">
    <color rgba="0.5 0.5 0.5 1.0" />
  </material>

  <material name="orange">
    <color rgba="1.0 0.4235 0.0392 1.0" />
  </material>

  <material name="brown">
    <color rgba="0.8706 0.8118 0.7647 1.0" />
  </material>

  <material name="red">
    <color rgba="0.8 0.0 0.0 1.0" />
  </material>

  <material name="white">
    <color rgba="1.0 1.0 1.0 1.0" />
  </material>

  <!-- Base Footprint -->
  <link name="base_footprint" />

  <joint name="base_joint" type="fixed">
    <parent link="base_footprint" />
    <child link="base_link" />
    <origin xyz="0.0 0.0 0.010" rpy="0 0 0" />
  </joint>

  <!-- Base Link -->
  <link name="base_link">
    <visual>
      <origin xyz="-0.032 0 0.0" rpy="0 0 0" />
      <geometry>
        <mesh filename="package://catapaf_gazebo/models/catapaf_common/meshes/bases/burger_base.stl"
          scale="0.001 0.001 0.001" />
      </geometry>
      <material name="light_black" />
    </visual>

    <collision>
      <origin xyz="-0.032 0 0.070" rpy="0 0 0" />
      <geometry>
        <box size="0.140 0.140 0.143" />
      </geometry>
    </collision>

    <inertial>
      <origin xyz="0 0 0" rpy="0 0 0" />
      <mass value="8.2573504e-01" />
      <inertia ixx="2.2124416e-03" ixy="0.0" ixz="0.0" iyy="2.1193702e-03" iyz="0.0" izz="2.0064271e-03"/>
    </inertial>
  </link>

  <!-- Wheels -->
  <joint name="wheel_left_joint" type="continuous">
    <parent link="base_link" />
    <child link="wheel_left_link" />
    <origin xyz="0.0 0.08 0.023" rpy="-1.57 0 0" />
    <axis xyz="0 0 1" />
    <dynamics damping="0.5" friction="0.2" />
  </joint>

  <link name="wheel_left_link">
    <visual>
      <origin xyz="0 0 0" rpy="1.57 0 0" />
      <geometry>
        <mesh filename="package://catapaf_gazebo/models/catapaf_common/meshes/wheels/left_tire.stl"
          scale="0.001 0.001 0.001" />
      </geometry>
      <material name="dark" />
    </visual>

    <collision>
      <origin xyz="0 0 0" rpy="0 0 0" />
      <geometry>
        <cylinder length="0.018" radius="0.033" />
      </geometry>
      <surface>
        <friction>
          <ode>
            <mu>2.0</mu>
            <mu2>2.0</mu2>
          </ode>
        </friction>
      </surface>
    </collision>

    <inertial>
      <origin xyz="0 0 0" />
      <mass value="2.8498940e-02" />
      <inertia ixx="1.1175580e-05" ixy="0.0" ixz="0.0" iyy="1.1192413e-05" iyz="0.0" izz="2.0712558e-05"/>
    </inertial>
  </link>

  <joint name="wheel_right_joint" type="continuous">
    <parent link="base_link" />
    <child link="wheel_right_link" />
    <origin xyz="0.0 -0.080 0.023" rpy="-1.57 0 0" />
    <axis xyz="0 0 1" />
    <dynamics damping="0.5" friction="0.2" />
  </joint>

  <link name="wheel_right_link">
    <visual>
      <origin xyz="0 0 0" rpy="1.57 0 0" />
      <geometry>
        <mesh filename="package://catapaf_gazebo/models/catapaf_common/meshes/wheels/right_tire.stl"
          scale="0.001 0.001 0.001" />
      </geometry>
      <material name="dark" />
    </visual>

    <collision>
      <origin xyz="0 0 0" rpy="0 0 0" />
      <geometry>
        <cylinder length="0.018" radius="0.033" />
      </geometry>
      <surface>
        <friction>
          <ode>
            <mu>2.0</mu>
            <mu2>2.0</mu2>
          </ode>
        </friction>
      </surface>
    </collision>

    <inertial>
      <origin xyz="0 0 0" />
      <mass value="2.8498940e-02" />
      <inertia ixx="1.1175580e-05" ixy="0.0" ixz="0.0" iyy="1.1192413e-05" iyz="0.0" izz="2.0712558e-05"/>
    </inertial>
  </link>

  <!-- Caster Wheel -->
  <joint name="caster_back_joint" type="fixed">
    <parent link="base_link" />
    <child link="caster_back_link" />
    <origin xyz="-0.081 0 -0.004" rpy="-1.57 0 0" />
  </joint>

  <link name="caster_back_link">
    <collision>
      <origin xyz="0 0.001 0" rpy="0 0 0" />
      <geometry>
        <box size="0.030 0.009 0.020" />
      </geometry>
    </collision>

    <inertial>
      <origin xyz="0 0 0" />
      <mass value="0.005" />
      <inertia ixx="1.0e-07" ixy="0.0" ixz="0.0" iyy="1.0e-07" iyz="0.0" izz="1.0e-07"/>
    </inertial>
  </link>
  <joint name="support_cameras_a_joint" type="fixed">
    <parent link="base_link" />
    <child link="support_cameras_a_link" />
    <origin rpy="0 0 0" xyz="0.023 0 0.101" />
  </joint>
  <link name="support_cameras_a_link">
    <visual>
      <origin rpy="0 0 1.57" xyz="0 0 0" />
      <geometry>
        <mesh
          filename="package://catapaf_gazebo/models/catapaf_common/meshes/sensors/support_cameras_part_a.stl"
          scale="0.001 0.001 0.001" />
      </geometry>
      <material name="dark" />
    </visual>
    <collision>
      <origin rpy="0 0 1.57" xyz="0.036 0.0 0" />
      <geometry>
        <box size="0.09 0.03 0.015" />
      </geometry>
    </collision>
  </link>

  <joint name="support_cameras_b_joint" type="fixed">
    <parent link="support_cameras_a_link" />
    <child link="support_cameras_b_link" />
    <origin rpy="0 -1.57 0" xyz="0.0435 0 0" />
  </joint>
  <link name="support_cameras_b_link">
    <visual>
      <origin rpy="0 0 -1.57" xyz="0 0 0" />
      <geometry>
        <mesh
          filename="package://catapaf_gazebo/models/catapaf_common/meshes/sensors/support_cameras_part_b.stl"
          scale="0.001 0.001 0.001" />
      </geometry>
      <material name="dark" />
    </visual>
    <collision>
      <origin rpy="0 0 -1.57" xyz="0.018 0 0" />
      <geometry>
        <box size="0.09 0.025 0.015" />
      </geometry>
    </collision>
  </link>
  <!-- IMU -->
  <joint name="imu_joint" type="fixed">
    <parent link="base_link" />
    <child link="imu_link" />
    <origin xyz="-0.032 0 0.068" rpy="0 0 0" />
  </joint>

  <link name="imu_link" />

  <!-- LiDAR -->
  <joint name="scan_joint" type="fixed">
    <parent link="base_link" />
    <child link="base_scan" />
    <origin xyz="-0.032 0 0.172" rpy="0 0 0" />
  </joint>

  <link name="base_scan">
    <visual>
      <origin xyz="0 0 0.0" rpy="0 0 0" />
      <geometry>
        <mesh filename="package://catapaf_gazebo/models/catapaf_common/meshes/sensors/lds.stl"
          scale="0.001 0.001 0.001" />
      </geometry>
      <material name="dark" />
    </visual>

    <collision>
      <origin xyz="0.015 0 -0.0065" rpy="0 0 0" />
      <geometry>
        <cylinder length="0.0315" radius="0.055" />
      </geometry>
    </collision>

    <inertial>
      <mass value="0.114" />
      <origin xyz="0 0 0" />
      <inertia ixx="47.43e-06" ixy="0.0" ixz="0.0" iyy="79.51e-06" iyz="0.0" izz="102.75e-06"/>
    </inertial>
  </link>

  <!-- OAK-D Pro Camera -->
  <!-- <link name="oak_d_pro_camera">
    <visual>
      <origin xyz="0 0 0" rpy="3.14 0 1.57" />
      <geometry>
        <mesh filename="package://catapaf_gazebo/models/catapaf_common/meshes/sensors/OAK-D-PRO.stl" />
      </geometry>
    </visual>
    <collision>
      <origin xyz="0 -0.005 -0.01" />
      <geometry>
        <box size="0.1 0.03 0.02" />
      </geometry>
    </collision>
    <inertial>
      <origin xyz="0 0 0" />
      <mass value="0.09100000" />
      <inertia ixx="0.00000975" ixy="0.0" ixz="0.0" iyy="0.00007087" iyz="0.0" izz="0.00007312" />
    </inertial>
  </link> -->

  <!-- <joint name="joint_oak_d_pro_camera" type="fixed">
    <parent link="support_cameras_b_link" />
    <child link="oak_d_pro_camera" />
    <origin xyz="0.0315 -0.0015 -0.03" rpy="0 0 0" />
  </joint>

  <link name="oak_d_pro_color_optical_frame" />
  <joint name="joint_oak_d_pro_color_optical_frame" type="fixed">
    <parent link="oak_d_pro_camera" />
    <child link="oak_d_pro_color_optical_frame" />
    <origin xyz="0.0 0.0 0.0" rpy="0 0 1.5708" />

  </joint>

  <link name="oak_d_pro_depth_optical_frame" />
  <joint name="joint_oak_d_pro_depth_optical_frame" type="fixed">
    <parent link="oak_d_pro_camera" />
    <child link="oak_d_pro_depth_optical_frame" />
    <origin xyz="0.0 0.0 0.0" rpy="-1.5708 0 -1.5708" />
  </joint> -->
  <link name="oak_d_pro_camera">
    <visual name="meshes">
      <origin xyz="0.0 0.0 0.0" rpy="0 0 0" />
      <geometry>
        <mesh filename="package://catapaf_gazebo/models/catapaf_common/meshes/sensors/OAK-D-PRO.stl"
          scale="1.0 1.0 1.0" />
      </geometry>
      <material name="dark" />
    </visual>
    <inertial>
      <origin xyz="0.0 0.0 0.0" />
      <mass value="0.09100000" />
      <inertia ixx="0.00000975" ixy="0.0" ixz="0.0" iyy="0.00007087" iyz="0.0" izz="0.00007312" />
    </inertial>
    <collision>
      <origin rpy="0.0 0.0 0.0" xyz="0 -0.005 -0.01" />
      <geometry>
        <box size="0.1 0.03 0.02" />
      </geometry>
    </collision>
  </link>
  <joint name="joint_oak_d_pro_camera" type="fixed">
    <parent link="support_cameras_b_link" />
    <child link="oak_d_pro_camera" />
    <origin xyz="0.0315 -0.0015 -0.03" rpy="3.14 0 1.57" />
  </joint>

  <link name="oak_d_pro_color_optical_frame" />
  <joint name="joint_oak_d_pro_color_optical_frame" type="fixed">
    <parent link="oak_d_pro_camera" />
    <child link="oak_d_pro_color_optical_frame" />
    <origin xyz="0.0 0.0 0.0" rpy="-1.57 -1.57 0" />
  </joint>

  <link name="oak_d_pro_depth_optical_frame" />
  <joint name="joint_oak_d_pro_depth_optical_frame" type="fixed">
    <parent link="oak_d_pro_camera" />
    <child link="oak_d_pro_depth_optical_frame" />
    <origin xyz="0.0 0.0 0.0" rpy="-1.57 -1.57 0" />
  </joint>

  <!-- Catapaf Base -->
  <link name="catapaf_base">
    <visual>
      <geometry>
        <mesh
          filename="package://catapaf_gazebo/models/catapaf_common/meshes/catapaf/baseEtServo.stl" />
      </geometry>
      <material name="dark" />
    </visual>
    <collision>
      <origin xyz="-0.008 0.02 0" />
      <geometry>
        <box size="0.08 0.05 0.03" />
      </geometry>
    </collision>
    <inertial>
      <origin xyz="0 0 0" />
      <mass value="0.15" />
      <inertia ixx="0.00002827111577" ixy="0.0" ixz="0.0" iyy="0.00002166454804" iyz="0.0" izz="0.00004287492870"/>
    </inertial>
  </link>

  <joint name="catapaf_base_mount" type="fixed">
    <parent link="base_link" />
    <child link="catapaf_base" />
    <origin xyz="-0.03 -0.09 0.11" />
  </joint>

  <!-- Catapaf Arm -->
  <link name="catapaf_arm">
    <visual>
      <geometry>
        <mesh filename="package://catapaf_gazebo/models/catapaf_common/meshes/catapaf/godetrvcm.stl" />
      </geometry>
      <material name="dark" />
    </visual>
    <collision>
      <origin xyz="0.0 0 0" />
      <geometry>
        <mesh
          filename="package://catapaf_gazebo/models/catapaf_common/meshes/catapaf/collider_godet.stl" />
      </geometry>
      <surface>
        <contact>
          <collide_without_contact>true</collide_without_contact>
        </contact>
      </surface>
    </collision>
    <inertial>
      <origin xyz="0.05596964 -0.00000099 -0.00621362" />
      <mass value="0.05000000" />
      <inertia ixx="0.00000512" ixy="-0.00000000" ixz="0.00000175" iyy="0.00003787" iyz="0.00000000"
        izz="0.00003918" />
    </inertial>
  </link>

  <joint name="catapaf_joint" type="revolute">
    <parent link="catapaf_base" />
    <child link="catapaf_arm" />
    <origin xyz="0 -0.008 0" rpy="3.14159265359 3.14159265359 0" />
    <axis xyz="0 1 0" />
    <limit effort="1.0" lower="-1.5" upper="0.2" velocity="5.0" />
    <dynamics damping="1" friction="0.5" />
  </joint>


  <!-- Gazebo Sensor Plugins -->
  <gazebo reference="imu_link">
    <sensor name="tb3_imu" type="imu">
      <always_on>true</always_on>
      <update_rate>200</update_rate>
      <topic>imu</topic>
      <imu>
        <angular_velocity>
          <x>
            <noise type="gaussian">
              <mean>0.0</mean>
              <stddev>2e-4</stddev>
            </noise>
          </x>
          <y>
            <noise type="gaussian">
              <mean>0.0</mean>
              <stddev>2e-4</stddev>
            </noise>
          </y>
          <z>
            <noise type="gaussian">
              <mean>0.0</mean>
              <stddev>2e-4</stddev>
            </noise>
          </z>
        </angular_velocity>
        <linear_acceleration>
          <x>
            <noise type="gaussian">
              <mean>0.0</mean>
              <stddev>1.7e-2</stddev>
            </noise>
          </x>
          <y>
            <noise type="gaussian">
              <mean>0.0</mean>
              <stddev>1.7e-2</stddev>
            </noise>
          </y>
          <z>
            <noise type="gaussian">
              <mean>0.0</mean>
              <stddev>1.7e-2</stddev>
            </noise>
          </z>
        </linear_acceleration>
      </imu>
    </sensor>
  </gazebo>

  <gazebo reference="base_scan">
    <sensor name="hls_lfcd_lds" type="gpu_lidar">
      <always_on>true</always_on>
      <visualize>true</visualize>
      <pose>-0.032 0 0.171 0 0 0</pose>
      <update_rate>5</update_rate>
      <topic>scan</topic>
      <gz_frame_id>base_scan</gz_frame_id>
      <lidar>
        <scan>
          <horizontal>
            <samples>360</samples>
            <resolution>1.000000</resolution>
            <min_angle>0.000000</min_angle>
            <max_angle>6.280000</max_angle>
          </horizontal>
        </scan>
        <range>
          <min>0.120000</min>
          <max>3.5</max>
          <resolution>0.015000</resolution>
        </range>
        <noise>
          <type>gaussian</type>
          <mean>0.0</mean>
          <stddev>0.01</stddev>
        </noise>
      </lidar>
    </sensor>
  </gazebo>

  <gazebo reference="oak_d_pro_color_optical_frame">
    <sensor name="rgb_camera" type="camera">
      <!-- <pose>0 0 0 0 0 0</pose> -->
      <always_on>1</always_on>
      <update_rate>30</update_rate>
      <visualize>true</visualize>
      <topic>camera/image_raw</topic>
      <gz_frame_id>oak_d_pro_color_optical_frame</gz_frame_id>
      <camera>
        <horizontal_fov>1.047</horizontal_fov> <!-- 60 degrés -->
        <image>
          <width>640</width>
          <height>480</height>
          <format>RGB_INT8</format>
        </image>
        <clip>
          <near>0.1</near>
          <far>100</far>
        </clip>
      </camera>
    </sensor>
  </gazebo>

  <gazebo reference="oak_d_pro_depth_optical_frame">
    <sensor name="depth_camera" type="depth_camera">
      <always_on>1</always_on>
      <update_rate>30</update_rate>
      <visualize>true</visualize>
      <topic>depth_camera/image</topic>
      <gz_frame_id>oak_d_pro_depth_optical_frame</gz_frame_id>
      <camera>
        <horizontal_fov>1.047</horizontal_fov>
        <image>
          <width>640</width>
          <height>480</height>
          <format>R_FLOAT32</format>
        </image>
        <clip>
          <near>0.1</near>
          <far>100.0</far>
        </clip>
      </camera>
    </sensor>
  </gazebo>

  <!-- Gazebo Plugins -->
  <gazebo>
    <plugin filename="gz-sim-diff-drive-system" name="gz::sim::systems::DiffDrive">
      <!-- wheels -->
      <left_joint>wheel_left_joint</left_joint>
      <right_joint>wheel_right_joint</right_joint>

      <!-- kinematics -->
      <wheel_separation>0.160</wheel_separation>
      <wheel_radius>0.033</wheel_radius>

      <!-- limits -->
      <max_linear_acceleration>1.0</max_linear_acceleration>

      <topic>cmd_vel</topic>
      <odom_topic>odom</odom_topic>
      <frame_id>odom</frame_id>
      <tf_topic>/tf</tf_topic>
      <odom_publisher_frequency>30</odom_publisher_frequency>
      <child_frame_id>base_footprint</child_frame_id>
    </plugin>
  </gazebo>

  <gazebo>
    <plugin filename="gz-sim-joint-state-publisher-system"
      name="gz::sim::systems::JointStatePublisher">
      <topic>joint_states</topic>
      <joint_name>wheel_left_joint</joint_name>
      <joint_name>wheel_right_joint</joint_name>
      <joint_name>catapaf_joint</joint_name>
    </plugin>
  </gazebo>

  <gazebo>
    <plugin filename="gz-sim-joint-position-controller-system"
      name="gz::sim::systems::JointPositionController">
      <joint_name>catapaf_joint</joint_name>
      <topic>catapaf_arm/position</topic>
      <p_gain>3.0</p_gain>
      <i_gain>0.0</i_gain>
      <d_gain>2.0</d_gain>
      <i_max>0.5</i_max>
      <i_min>-0.5</i_min>
      <cmd_max>10.0</cmd_max>
      <cmd_min>-10.0</cmd_min>
    </plugin>
  </gazebo>
</robot>