<?xml version="1.0"?>
<robot name="turtlebot3_burger_cam1"
  xmlns:xacro="http://ros.org/wiki/xacro">

  <material name="black">
    <color rgba="0.0 0.0 0.0 1.0" />
  </material>

  <material name="dark">
    <color rgba="0.3 0.3 0.3 1.0" />
  </material>

  <material name="light_black">
    <color rgba="0.4 0.4 0.4 1.0" />
  </material>

  <material name="blue">
    <color rgba="0.0 0.0 0.8 1.0" />
  </material>

  <material name="green">
    <color rgba="0.0 0.8 0.0 1.0" />
  </material>

  <material name="grey">
    <color rgba="0.5 0.5 0.5 1.0" />
  </material>

  <material name="orange">
    <color rgba="1.0 0.4235 0.0392 1.0" />
  </material>

  <material name="brown">
    <color rgba="0.8706 0.8118 0.7647 1.0" />
  </material>

  <material name="red">
    <color rgba="0.8 0.0 0.0 1.0" />
  </material>

  <material name="white">
    <color rgba="1.0 1.0 1.0 1.0" />
  </material>

  <link name="base_footprint" />

  <joint name="base_joint" type="fixed">
    <parent link="base_footprint" />
    <child link="base_link" />
    <origin xyz="0.0 0.0 0.010" rpy="0 0 0" />
  </joint>

  <link name="base_link">
    <visual>
      <origin xyz="-0.032 0 0.0" rpy="0 0 0" />
      <geometry>
        <mesh filename="package://catapaf_gazebo/models/catapaf_common/meshes/bases/burger_base.stl"
          scale="0.001 0.001 0.001" />
      </geometry>
      <material name="light_black" />
    </visual>

    <collision>
      <origin xyz="-0.032 0 0.070" rpy="0 0 0" />
      <geometry>
        <box size="0.140 0.140 0.143" />
      </geometry>
    </collision>

    <inertial>
      <origin xyz="0 0 0" rpy="0 0 0" />
      <mass value="8.2573504e-01" />
      <inertia ixx="2.2124416e-03" ixy="-1.2294101e-05" ixz="3.4938785e-05" iyy="2.1193702e-03"
        iyz="-5.0120904e-06" izz="2.0064271e-03" />
    </inertial>
  </link>

  <joint name="wheel_left_joint" type="continuous">
    <parent link="base_link" />
    <child link="wheel_left_link" />
    <origin xyz="0.0 0.08 0.023" rpy="-1.57 0 0" />
    <axis xyz="0 0 1" />
  </joint>

  <link name="wheel_left_link">
    <visual>
      <origin xyz="0 0 0" rpy="1.57 0 0" />
      <geometry>
        <mesh filename="package://catapaf_gazebo/models/catapaf_common/meshes/wheels/left_tire.stl"
          scale="0.001 0.001 0.001" />
      </geometry>
      <material name="dark" />
    </visual>

    <collision>
      <origin xyz="0 0 0" rpy="0 0 0" />
      <geometry>
        <cylinder length="0.018" radius="0.033" />
      </geometry>
    </collision>

    <inertial>
      <origin xyz="0 0 0" />
      <mass value="2.8498940e-02" />
      <inertia ixx="1.1175580e-05" ixy="-4.2369783e-11" ixz="-5.9381719e-09" iyy="1.1192413e-05"
        iyz="-1.4400107e-11" izz="2.0712558e-05" />
    </inertial>
  </link>

  <joint name="wheel_right_joint" type="continuous">
    <parent link="base_link" />
    <child link="wheel_right_link" />
    <origin xyz="0.0 -0.080 0.023" rpy="-1.57 0 0" />
    <axis xyz="0 0 1" />
  </joint>

  <link name="wheel_right_link">
    <visual>
      <origin xyz="0 0 0" rpy="1.57 0 0" />
      <geometry>
        <mesh filename="package://catapaf_gazebo/models/catapaf_common/meshes/wheels/right_tire.stl"
          scale="0.001 0.001 0.001" />
      </geometry>
      <material name="dark" />
    </visual>

    <collision>
      <origin xyz="0 0 0" rpy="0 0 0" />
      <geometry>
        <cylinder length="0.018" radius="0.033" />
      </geometry>
    </collision>

    <inertial>
      <origin xyz="0 0 0" />
      <mass value="2.8498940e-02" />
      <inertia ixx="1.1175580e-05" ixy="-4.2369783e-11" ixz="-5.9381719e-09" iyy="1.1192413e-05"
        iyz="-1.4400107e-11" izz="2.0712558e-05" />
    </inertial>
  </link>

  <joint name="caster_back_joint" type="fixed">
    <parent link="base_link" />
    <child link="caster_back_link" />
    <origin xyz="-0.081 0 -0.004" rpy="-1.57 0 0" />
  </joint>

  <link name="caster_back_link">
    <collision>
      <origin xyz="0 0.001 0" rpy="0 0 0" />
      <geometry>
        <box size="0.030 0.009 0.020" />
      </geometry>
    </collision>

    <inertial>
      <origin xyz="0 0 0" />
      <mass value="0.005" />
      <inertia ixx="0.001" ixy="0.0" ixz="0.0" iyy="0.001" iyz="0.0" izz="0.001" />
    </inertial>
  </link>

  <joint name="imu_joint" type="fixed">
    <parent link="base_link" />
    <child link="imu_link" />
    <origin xyz="-0.032 0 0.068" rpy="0 0 0" />
  </joint>

  <link name="imu_link" />

  <joint name="scan_joint" type="fixed">
    <parent link="base_link" />
    <child link="base_scan" />
    <origin xyz="-0.032 0 0.172" rpy="0 0 0" />
  </joint>

  <link name="base_scan">
    <visual>
      <origin xyz="0 0 0.0" rpy="0 0 0" />
      <geometry>
        <mesh filename="package://catapaf_gazebo/models/catapaf_common/meshes/sensors/lds.stl"
          scale="0.001 0.001 0.001" />
      </geometry>
      <material name="dark" />
    </visual>

    <collision>
      <origin xyz="0.015 0 -0.0065" rpy="0 0 0" />
      <geometry>
        <cylinder length="0.0315" radius="0.055" />
      </geometry>
    </collision>

    <inertial>
      <mass value="0.114" />
      <origin xyz="0 0 0" />
      <inertia ixx="0.001" ixy="0.0" ixz="0.0" iyy="0.001" iyz="0.0" izz="0.001" />
    </inertial>
  </link>

  <!-- OAK-D Pro Camera -->
  <link name="oak_d_pro_camera">
    <visual>
      <origin xyz="0 0 0" rpy="0 0 1.5707" />
      <geometry>
        <mesh filename="package://catapaf_gazebo/models/catapaf_common/meshes/sensors/OAK-D-PRO.stl" />
      </geometry>
    </visual>
    <collision>
      <origin xyz="0 -0.005 -0.01" />
      <geometry>
        <box size="0.1 0.03 0.02" />
      </geometry>
    </collision>
    <inertial>
      <origin xyz="0 0 0" />
      <mass value="0.091" />
      <inertia ixx="1e-4" ixy="0.0" ixz="0.0" iyy="1e-4" iyz="0.0" izz="1e-4" />
    </inertial>
  </link>

  <joint name="joint_oak_d_pro_camera" type="fixed">
    <parent link="base_link" />
    <child link="oak_d_pro_camera" />
    <origin xyz="0.065 0 0.11" rpy="0 0 0" />
  </joint>

  <link name="oak_d_pro_color_optical_frame" />
  <joint name="joint_oak_d_pro_color_optical_frame" type="fixed">
    <parent link="oak_d_pro_camera" />
    <child link="oak_d_pro_color_optical_frame" />
    <origin xyz="0 0 0" rpy="-1.5707 0 -1.5707" />
  </joint>

  <link name="oak_d_pro_depth_optical_frame" />
  <joint name="joint_oak_d_pro_depth_optical_frame" type="fixed">
    <parent link="oak_d_pro_camera" />
    <child link="oak_d_pro_depth_optical_frame" />
    <origin xyz="0 0 0" rpy="-1.5707 0 -1.5707" />
  </joint>

  <!-- Catapaf Base -->
  <link name="catapaf_base">
    <visual>
      <geometry>
        <mesh
          filename="package://catapaf_gazebo/models/catapaf_common/meshes/catapaf/baseEtServo.stl" />
      </geometry>
    </visual>
    <collision>
      <origin xyz="-0.008 0.02 0" />
      <geometry>
        <box size="0.08 0.05 0.03" />
      </geometry>
    </collision>
    <inertial>
      <origin xyz="0 0 0" />
      <mass value="0.15" />
      <inertia ixx="0.0002" ixy="0" ixz="0" iyy="0.0002" iyz="0" izz="0.0002" />
    </inertial>
  </link>

  <joint name="catapaf_base_mount" type="fixed">
    <parent link="base_link" />
    <child link="catapaf_base" />
    <origin xyz="-0.03 -0.09 0.11" />
  </joint>

  <!-- Catapaf Arm -->
  <link name="catapaf_arm">
    <visual>
      <geometry>
        <mesh filename="package://catapaf_gazebo/models/catapaf_common/meshes/catapaf/godetrvcm.stl" />
      </geometry>
    </visual>
    <collision>
      <origin xyz="0.0 0 0" />
      <geometry>
        <mesh filename="package://catapaf_gazebo/models/catapaf_common/meshes/catapaf/collider_godet.stl" />
      </geometry>
    </collision>
    <inertial>
      <origin xyz="0.05596964 -0.00000099 -0.00621362" />
      <mass value="0.05000000" />
      <inertia ixx="0.00000512" ixy="-0.00000000" ixz="0.00000175" iyy="0.00003787" iyz="0.00000000"
        izz="0.00003918" />
    </inertial>
  </link>

  <joint name="catapaf_joint" type="revolute">
    <parent link="catapaf_base" />
    <child link="catapaf_arm" />
    <origin xyz="0 -0.008 0" rpy="3.14159265359 3.14159265359 0" />
    <axis xyz="0 1 0" />
    <limit effort="1.0" lower="-1.5" upper="1.3" velocity="5.0" />
  </joint>

</robot>